2024-08-02 20:29:45,317 | WARNING | Неверный тип данных для объекта Runner
Traceback (most recent call last):
  File "D:\PythonProjects\Urban_University\Homework_48\test_12_4.py", line 20, in test_run
    object_runner = rt_with_exceptions.Runner(404, 50)
                    ^^^^^^^^^^^^^^^^^^^^^^^^^^^^^^^^^^
  File "D:\PythonProjects\Urban_University\Homework_48\rt_with_exceptions.py", line 6, in __init__
    raise TypeError(f'Имя может быть только числом, передано {type(name).__name__}')
TypeError: Имя может быть только числом, передано int
2024-08-02 20:29:45,318 | WARNING | Неверная скорость для Runner
Traceback (most recent call last):
  File "D:\PythonProjects\Urban_University\Homework_48\test_12_4.py", line 10, in test_walk
    object_runner = rt_with_exceptions.Runner('Alex', -50)
                    ^^^^^^^^^^^^^^^^^^^^^^^^^^^^^^^^^^^^^^
  File "D:\PythonProjects\Urban_University\Homework_48\rt_with_exceptions.py", line 11, in __init__
    raise ValueError(f'Скорость не может быть отрицательной, сейчас {speed}')
ValueError: Скорость не может быть отрицательной, сейчас -50
